Workbook

Sheet Agenda
B2: WELLNESS — 3 DIAS — 8 SEMANAS
B4: Segunda, quarta e sexta. Inferiores I → II → III e superiores I → II seguem sua própria sequência entre as semanas.
B7: Semana | C7: Sessão | D7: Dia | E7: Treino | F7: PDF (página) | G7: Abrir | H7: Concluído
B8: 1 | C8: A1 | D8: Segunda | E8: Pernas/glúteos I | F8: 18 | G8: =HYPERLINK("#'S1 A1'!B1","Abrir") -> Abrir | H8: ='S1 A1'!F54 -> Não
B9: 1 | C9: A2 | D9: Quarta | E9: Superior I | F9: 19 | G9: =HYPERLINK("#'S1 A2'!B1","Abrir") -> Abrir | H9: ='S1 A2'!F55 -> Não
B10: 1 | C10: A3 | D10: Sexta | E10: Pernas/glúteos II | F10: 20 | G10: =HYPERLINK("#'S1 A3'!B1","Abrir") -> Abrir | H10: ='S1 A3'!F46 -> Não
B11: 2 | C11: A1 | D11: Segunda | E11: Superior II | F11: 21 | G11: =HYPERLINK("#'S2 A1'!B1","Abrir") -> Abrir | H11: ='S2 A1'!F46 -> Não
B12: 2 | C12: A2 | D12: Quarta | E12: Pernas/glúteos III | F12: 23 | G12: =HYPERLINK("#'S2 A2'!B1","Abrir") -> Abrir | H12: ='S2 A2'!F54 -> Não
B13: 2 | C13: A3 | D13: Sexta | E13: Superior I | F13: 19 | G13: =HYPERLINK("#'S2 A3'!B1","Abrir") -> Abrir | H13: ='S2 A3'!F55 -> Não
B14: 3 | C14: A1 | D14: Segunda | E14: Pernas/glúteos I | F14: 26 | G14: =HYPERLINK("#'S3 A1'!B1","Abrir") -> Abrir | H14: ='S3 A1'!F54 -> Não
B15: 3 | C15: A2 | D15: Quarta | E15: Superior II | F15: 29 | G15: =HYPERLINK("#'S3 A2'!B1","Abrir") -> Abrir | H15: ='S3 A2'!F46 -> Não
B16: 3 | C16: A3 | D16: Sexta | E16: Pernas/glúteos II | F16: 28 | G16: =HYPERLINK("#'S3 A3'!B1","Abrir") -> Abrir | H16: ='S3 A3'!F46 -> Não
B17: 4 | C17: A1 | D17: Segunda | E17: Superior I | F17: 27 | G17: =HYPERLINK("#'S4 A1'!B1","Abrir") -> Abrir | H17: ='S4 A1'!F55 -> Não
B18: 4 | C18: A2 | D18: Quarta | E18: Pernas/glúteos III | F18: 31 | G18: =HYPERLINK("#'S4 A2'!B1","Abrir") -> Abrir | H18: ='S4 A2'!F54 -> Não
B19: 4 | C19: A3 | D19: Sexta | E19: Superior II | F19: 29 | G19: =HYPERLINK("#'S4 A3'!B1","Abrir") -> Abrir | H19: ='S4 A3'!F46 -> Não
B20: 5 | C20: A1 | D20: Segunda | E20: Pernas/glúteos I | F20: 34 | G20: =HYPERLINK("#'S5 A1'!B1","Abrir") -> Abrir | H20: ='S5 A1'!F54 -> Não
B21: 5 | C21: A2 | D21: Quarta | E21: Superior I | F21: 35 | G21: =HYPERLINK("#'S5 A2'!B1","Abrir") -> Abrir | H21: ='S5 A2'!F55 -> Não
B22: 5 | C22: A3 | D22: Sexta | E22: Pernas/glúteos II | F22: 36 | G22: =HYPERLINK("#'S5 A3'!B1","Abrir") -> Abrir | H22: ='S5 A3'!F46 -> Não
B23: 6 | C23: A1 | D23: Segunda | E23: Superior II | F23: 37 | G23: =HYPERLINK("#'S6 A1'!B1","Abrir") -> Abrir | H23: ='S6 A1'!F46 -> Não
B24: 6 | C24: A2 | D24: Quarta | E24: Pernas/glúteos III | F24: 39 | G24: =HYPERLINK("#'S6 A2'!B1","Abrir") -> Abrir | H24: ='S6 A2'!F54 -> Não
B25: 6 | C25: A3 | D25: Sexta | E25: Superior I | F25: 35 | G25: =HYPERLINK("#'S6 A3'!B1","Abrir") -> Abrir | H25: ='S6 A3'!F55 -> Não
B26: 7 | C26: A1 | D26: Segunda | E26: Pernas/glúteos I | F26: 42 | G26: =HYPERLINK("#'S7 A1'!B1","Abrir") -> Abrir | H26: ='S7 A1'!F54 -> Não
B27: 7 | C27: A2 | D27: Quarta | E27: Superior II | F27: 45 | G27: =HYPERLINK("#'S7 A2'!B1","Abrir") -> Abrir | H27: ='S7 A2'!F46 -> Não
B28: 7 | C28: A3 | D28: Sexta | E28: Pernas/glúteos II | F28: 44 | G28: =HYPERLINK("#'S7 A3'!B1","Abrir") -> Abrir | H28: ='S7 A3'!F46 -> Não
B29: 8 | C29: A1 | D29: Segunda | E29: Superior I | F29: 43 | G29: =HYPERLINK("#'S8 A1'!B1","Abrir") -> Abrir | H29: ='S8 A1'!F55 -> Não
B30: 8 | C30: A2 | D30: Quarta | E30: Pernas/glúteos III | F30: 47 | G30: =HYPERLINK("#'S8 A2'!B1","Abrir") -> Abrir | H30: ='S8 A2'!F54 -> Não
B31: 8 | C31: A3 | D31: Sexta | E31: Superior II | F31: 45 | G31: =HYPERLINK("#'S8 A3'!B1","Abrir") -> Abrir | H31: ='S8 A3'!F46 -> Não
B34: COMO USAR
B36: As abas S1 A1, S1 A2 e S1 A3 são os treinos da semana 1. As demais seguem até S8 A3. Cada sessão conserva seu registro.
B38: Preencha o campo branco abaixo de Carga de Trabalho e a coluna Reps. Os campos amarelos à direita configuram cada equipamento.
B40: A carga calculada usa a mesma unidade da carga de trabalho. Por halter: informe um halter. Por lado: informe um lado. Total com barra: inclua a barra.
B42: Visor/pilha: anote o valor indicado. Total de anilhas: some as anilhas carregadas. Não há divisão automática por lados nem desconto de barra.
B44: O incremento é opcional e deve refletir a menor variação disponível no registro escolhido. O arredondamento é para baixo, por série.
B46: Feeder sets: 3 FS = 50%, 70%, 85%; 2 FS = 70%, 85%; 1 FS = 85% da WS. O PDF permite 85–90% no último FS: adotados 85%.
B48: Top set = 110% da WS. Exceção: terra sumô nas semanas 3–4 = 108%. Back off = 75% da WS, inclusive quando vem após top set.
B50: Aquecimento = 30% da WS como na PURGE; esse percentual não é informado no PDF. Descanso fica em branco para definição individual.
B52: Não há aumento automático de carga entre sessões: registre a evolução de cargas e repetições, conforme descrito no PDF.
B54: A frequência foi adaptada de 5 para 3 sessões. Foram mantidos os exercícios e as séries de cada sessão escolhida, sem juntar sessões.
B56: As fases 1–2, 3–4, 5–6 e 7–8 seguem as semanas do calendário. Em 8 semanas são 24 sessões; a frequência e o volume diferem do plano original.
... B60: Fontes: PDF Wellness — Saraiva Team e PURGE. Adaptação: hack, leg press unilateral, flexora sentada e elevação pélvica; step up retirado.

Sheet S1 A1
B1: WELLNESS • SEMANA 1 • A1 | I1: Parâmetros editáveis
B3: Segunda-feira — Pernas e glúteos I | I3: Configure o registro e o incremento conforme o equipamento. Nenhuma carga inicial é presumida.
B4: Preencha a carga de trabalho e as repetições realizadas. Cargas em kg.
B5: Exercício | C5: Série | D5: Cargas | E5: Rep Range | F5: Reps | G5: Vídeo
B6: Cadeira abdutora | C6: Aquecimento | D6: =IF(ISNUMBER($B$9),IF(OR($J$9="",$J$9=0),$B$9*0.3,ROUNDDOWN($B$9*0.3/$J$9,0)*$J$9),"") -> 1.5 | E6: 10 - 15 | G6: =HYPERLINK("https://www.youtube.com/shorts/S9OtoSJdMWo","Link") -> Link | I6: Cadeira abdutora
C7: Feeder Set 1 | D7: =IF(ISNUMBER($B$9),IF(OR($J$9="",$J$9=0),$B$9*0.7,ROUNDDOWN($B$9*0.7/$J$9,0)*$J$9),"") -> 3.5 | E7: 3 - 5 | I7: Equipamento | J7: Máquina
B8: Carga de Trabalho | C8: Feeder Set 2 | D8: =IF(ISNUMBER($B$9),IF(OR($J$9="",$J$9=0),$B$9*0.85,ROUNDDOWN($B$9*0.85/$J$9,0)*$J$9),"") -> 4.25 | E8: 3 - 5 | I8: Como registrar | J8: Visor / pilha
B9: 5 | C9: Working Set 1 | D9: =IF(ISNUMBER($B$9),IF(OR($J$9="",$J$9=0),$B$9*1,ROUNDDOWN($B$9*1/$J$9,0)*$J$9),"") -> 5 | E9: 8 - 12 | I9: Incremento (kg) | K9: Descanso (s)
C10: Working Set 2 | D10: =IF(ISNUMBER($B$9),IF(OR($J$9="",$J$9=0),$B$9*1,ROUNDDOWN($B$9*1/$J$9,0)*$J$9),"") -> 5 | E10: 8 - 12 | I10: Incremento vazio: cálculo exato. Preenchido: arredonda para baixo.
C11: Working Set 3 | D11: =IF(ISNUMBER($B$9),IF(OR($J$9="",$J$9=0),$B$9*1,ROUNDDOWN($B$9*1/$J$9,0)*$J$9),"") -> 5 | E11: 8 - 12 | I11: PDF, p. 18. Descanso não especificado no original.
B12: Tronco levemente inclinado para frente. Aquecimento: 30% da WS, referência da PURGE; o PDF não define percentual.
B14: Cadeira flexora | C14: Feeder Set 1 | D14: =IF(ISNUMBER($B$17),IF(OR($J$17="",$J$17=0),$B$17*0.7,ROUNDDOWN($B$17*0.7/$J$17,0)*$J$17),"") | E14: 3 - 5 | G14: =HYPERLINK("https://www.youtube.com/watch?v=wqVoX6lbYf8","Link") -> Link | I14: Cadeira flexora
C15: Feeder Set 2 | D15: =IF(ISNUMBER($B$17),IF(OR($J$17="",$J$17=0),$B$17*0.85,ROUNDDOWN($B$17*0.85/$J$17,0)*$J$17),"") | E15: 3 - 5 | I15: Equipamento | J15: Máquina
B16: Carga de Trabalho | C16: Working Set 1 | D16: =IF(ISNUMBER($B$17),IF(OR($J$17="",$J$17=0),$B$17*1,ROUNDDOWN($B$17*1/$J$17,0)*$J$17),"") | E16: 8 | I16: Como registrar | J16: Visor / pilha
I17: Incremento (kg) | K17: Descanso (s)
I18: Incremento vazio: cálculo exato. Preenchido: arredonda para baixo.
I19: PDF, p. 18. Descanso não especificado no original.
B22: Hack squat | C22: Feeder Set 1 | D22: =IF(ISNUMBER($B$25),IF(OR($J$25="",$J$25=0),$B$25*0.5,ROUNDDOWN($B$25*0.5/$J$25,0)*$J$25),"") | E22: 3 - 5 | G22: =HYPERLINK("https://www.youtube.com/watch?v=rYgNArpwE7E","Link") -> Link | I22: Hack squat
C23: Feeder Set 2 | D23: =IF(ISNUMBER($B$25),IF(OR($J$25="",$J$25=0),$B$25*0.7,ROUNDDOWN($B$25*0.7/$J$25,0)*$J$25),"") | E23: 3 - 5 | I23: Equipamento | J23: Máquina
B24: Carga de Trabalho | C24: Feeder Set 3 | D24: =IF(ISNUMBER($B$25),IF(OR($J$25="",$J$25=0),$B$25*0.85,ROUNDDOWN($B$25*0.85/$J$25,0)*$J$25),"") | E24: 3 - 5 | I24: Como registrar | J24: Total de anilhas
C25: Working Set 1 | D25: =IF(ISNUMBER($B$25),IF(OR($J$25="",$J$25=0),$B$25*1,ROUNDDOWN($B$25*1/$J$25,0)*$J$25),"") | E25: 8 | I25: Incremento (kg) | K25: Descanso (s)
C26: Working Set 2 | D26: =IF(ISNUMBER($B$25),IF(OR($J$25="",$J$25=0),$B$25*1,ROUNDDOWN($B$25*1/$J$25,0)*$J$25),"") | E26: 8 | I26: Incremento vazio: cálculo exato. Preenchido: arredonda para baixo.
I27: Exercício adaptado. Séries e repetições do exercício substituído.
B28: Hack squat. Ajuste a carga neste equipamento; não copie os quilos do agachamento anterior.
B30: Cadeira extensora | C30: Feeder Set 1 | D30: =IF(ISNUMBER($B$33),IF(OR($J$33="",$J$33=0),$B$33*0.7,ROUNDDOWN($B$33*0.7/$J$33,0)*$J$33),"") | E30: 3 - 5 | G30: =HYPERLINK("https://www.youtube.com/watch?v=m0FOpMEgero","Link") -> Link | I30: Cadeira extensora
C31: Feeder Set 2 | D31: =IF(ISNUMBER($B$33),IF(OR($J$33="",$J$33=0),$B$33*0.85,ROUNDDOWN($B$33*0.85/$J$33,0)*$J$33),"") | E31: 3 - 5 | I31: Equipamento | J31: Máquina
B32: Carga de Trabalho | C32: Working Set 1 | D32: =IF(ISNUMBER($B$33),IF(OR($J$33="",$J$33=0),$B$33*1,ROUNDDOWN($B$33*1/$J$33,0)*$J$33),"") | E32: 8 | I32: Como registrar | J32: Visor / pilha
C33: Top Set | D33: =IF(ISNUMBER($B$33),IF(OR($J$33="",$J$33=0),$B$33*1.1,ROUNDDOWN($B$33*1.1/$J$33,0)*$J$33),"") | E33: 6 - 8 | I33: Incremento (kg) | K33: Descanso (s)
I34: Incremento vazio: cálculo exato. Preenchido: arredonda para baixo.
I35: PDF, p. 18. Descanso não especificado no original.
B38: Leg press unilateral | C38: Feeder Set 1 | D38: =IF(ISNUMBER($B$41),IF(OR($J$41="",$J$41=0),$B$41*0.85,ROUNDDOWN($B$41*0.85/$J$41,0)*$J$41),"") | E38: 3 - 5 | G38: =HYPERLINK("https://www.youtube.com/watch?v=9-JxC8XYqcI","Link") -> Link | I38: Leg press unilateral
C39: Working Set 1 | D39: =IF(ISNUMBER($B$41),IF(OR($J$41="",$J$41=0),$B$41*1,ROUNDDOWN($B$41*1/$J$41,0)*$J$41),"") | E39: 8 | I39: Equipamento | J39: Máquina
B40: Carga de Trabalho | C40: Top Set | D40: =IF(ISNUMBER($B$41),IF(OR($J$41="",$J$41=0),$B$41*1.1,ROUNDDOWN($B$41*1.1/$J$41,0)*$J$41),"") | E40: 6 - 8 | I40: Como registrar | J40: Por lado
I41: Incremento (kg) | K41: Descanso (s)
I42: Incremento vazio: cálculo exato. Preenchido: arredonda para baixo.
I43: Exercício adaptado. Séries e repetições do exercício substituído.
B44: Séries e repetições por perna. Registre a carga usada no aparelho para executar com uma perna.
B46: Elevação pélvica no smith, máquina ou livre | C46: Feeder Set 1 | D46: =IF(ISNUMBER($B$49),IF(OR($J$49="",$J$49=0),$B$49*0.85,ROUNDDOWN($B$49*0.85/$J$49,0)*$J$49),"") | E46: 3 - 5 | G46: =HYPERLINK("https://www.youtube.com/shorts/taUhr2s8Sf0","Link") -> Link | I46: Elevação pélvica no smith, máquina ou livre
C47: Working Set 1 | D47: =IF(ISNUMBER($B$49),IF(OR($J$49="",$J$49=0),$B$49*1,ROUNDDOWN($B$49*1/$J$49,0)*$J$49),"") | E47: 8 - 12 | I47: Equipamento | J47: Barra / smith
B48: Carga de Trabalho | C48: Working Set 2 | D48: =IF(ISNUMBER($B$49),IF(OR($J$49="",$J$49=0),$B$49*1,ROUNDDOWN($B$49*1/$J$49,0)*$J$49),"") | E48: 8 - 12 | I48: Como registrar | J48: Total com barra
...

Sheet S1 A2
B1: WELLNESS • SEMANA 1 • A2 | I1: Parâmetros editáveis
B3: Quarta-feira — Superiores I | I3: Configure o registro e o incremento conforme o equipamento. Nenhuma carga inicial é presumida.
B4: Preencha a carga de trabalho e as repetições realizadas. Cargas em kg.
B5: Exercício | C5: Série | D5: Cargas | E5: Rep Range | F5: Reps | G5: Vídeo
B6: Supino inclinado na máquina | C6: Aquecimento | D6: =IF(ISNUMBER($B$9),IF(OR($J$9="",$J$9=0),$B$9*0.3,ROUNDDOWN($B$9*0.3/$J$9,0)*$J$9),"") | E6: 10 - 15 | G6: =HYPERLINK("https://www.youtube.com/watch?v=TrTSvn5-MTk","Link") -> Link | I6: Supino inclinado na máquina
C7: Feeder Set 1 | D7: =IF(ISNUMBER($B$9),IF(OR($J$9="",$J$9=0),$B$9*0.5,ROUNDDOWN($B$9*0.5/$J$9,0)*$J$9),"") | E7: 3 | I7: Equipamento | J7: Máquina
B8: Carga de Trabalho | C8: Feeder Set 2 | D8: =IF(ISNUMBER($B$9),IF(OR($J$9="",$J$9=0),$B$9*0.7,ROUNDDOWN($B$9*0.7/$J$9,0)*$J$9),"") | E8: 3 | I8: Como registrar | J8: Visor / pilha
C9: Feeder Set 3 | D9: =IF(ISNUMBER($B$9),IF(OR($J$9="",$J$9=0),$B$9*0.85,ROUNDDOWN($B$9*0.85/$J$9,0)*$J$9),"") | E9: 3 | I9: Incremento (kg) | K9: Descanso (s)
C10: Working Set 1 | D10: =IF(ISNUMBER($B$9),IF(OR($J$9="",$J$9=0),$B$9*1,ROUNDDOWN($B$9*1/$J$9,0)*$J$9),"") | E10: 8 | I10: Incremento vazio: cálculo exato. Preenchido: arredonda para baixo.
C11: Top Set | D11: =IF(ISNUMBER($B$9),IF(OR($J$9="",$J$9=0),$B$9*1.1,ROUNDDOWN($B$9*1.1/$J$9,0)*$J$9),"") | E11: 6 - 8 | I11: PDF, p. 19. Descanso não especificado no original.
C12: Back Off | D12: =IF(ISNUMBER($B$9),IF(OR($J$9="",$J$9=0),$B$9*0.75,ROUNDDOWN($B$9*0.75/$J$9,0)*$J$9),"") | E12: 8 - 12
B13: Alternativa do PDF: halteres no banco em 30º. Aquecimento: 30% da WS, referência da PURGE; o PDF não define percentual.
B15: Elevação lateral com halteres sentada | C15: Feeder Set 1 | D15: =IF(ISNUMBER($B$18),IF(OR($J$18="",$J$18=0),$B$18*0.7,ROUNDDOWN($B$18*0.7/$J$18,0)*$J$18),"") | E15: 3 | G15: =HYPERLINK("https://www.youtube.com/shorts/Qy-zXcgZHWU","Link") -> Link | I15: Elevação lateral com halteres sentada
C16: Feeder Set 2 | D16: =IF(ISNUMBER($B$18),IF(OR($J$18="",$J$18=0),$B$18*0.85,ROUNDDOWN($B$18*0.85/$J$18,0)*$J$18),"") | E16: 3 | I16: Equipamento | J16: Halter
B17: Carga de Trabalho | C17: Working Set 1 | D17: =IF(ISNUMBER($B$18),IF(OR($J$18="",$J$18=0),$B$18*1,ROUNDDOWN($B$18*1/$J$18,0)*$J$18),"") | E17: 8 - 12 | I17: Como registrar | J17: Por halter
C18: Working Set 2 | D18: =IF(ISNUMBER($B$18),IF(OR($J$18="",$J$18=0),$B$18*1,ROUNDDOWN($B$18*1/$J$18,0)*$J$18),"") | E18: 8 - 12 | I18: Incremento (kg) | K18: Descanso (s)
C19: Working Set 3 | D19: =IF(ISNUMBER($B$18),IF(OR($J$18="",$J$18=0),$B$18*1,ROUNDDOWN($B$18*1/$J$18,0)*$J$18),"") | E19: 8 - 12 | I19: Incremento vazio: cálculo exato. Preenchido: arredonda para baixo.
I20: PDF, p. 19. Descanso não especificado no original.
B21: Braços esticados, levemente à frente do tronco.
B23: Remada articulada unilateral | C23: Feeder Set 1 | D23: =IF(ISNUMBER($B$26),IF(OR($J$26="",$J$26=0),$B$26*0.7,ROUNDDOWN($B$26*0.7/$J$26,0)*$J$26),"") | E23: 3 - 5 | G23: =HYPERLINK("https://www.youtube.com/watch?v=gnKmUlTOaCw","Link") -> Link | I23: Remada articulada unilateral
C24: Feeder Set 2 | D24: =IF(ISNUMBER($B$26),IF(OR($J$26="",$J$26=0),$B$26*0.85,ROUNDDOWN($B$26*0.85/$J$26,0)*$J$26),"") | E24: 3 - 5 | I24: Equipamento | J24: Polia
B25: Carga de Trabalho | C25: Working Set 1 | D25: =IF(ISNUMBER($B$26),IF(OR($J$26="",$J$26=0),$B$26*1,ROUNDDOWN($B$26*1/$J$26,0)*$J$26),"") | E25: 8 | I25: Como registrar | J25: Por lado
C26: Top Set | D26: =IF(ISNUMBER($B$26),IF(OR($J$26="",$J$26=0),$B$26*1.1,ROUNDDOWN($B$26*1.1/$J$26,0)*$J$26),"") | E26: 6 - 8 | I26: Incremento (kg) | K26: Descanso (s)
I27: Incremento vazio: cálculo exato. Preenchido: arredonda para baixo.
I28: PDF, p. 19. Descanso não especificado no original.
B29: Séries e reps por lado.
B31: Puxada alta com pegada neutra ou triângulo | C31: Feeder Set 1 | D31: =IF(ISNUMBER($B$34),IF(OR($J$34="",$J$34=0),$B$34*0.7,ROUNDDOWN($B$34*0.7/$J$34,0)*$J$34),"") | E31: 3 - 5 | G31: =HYPERLINK("https://www.youtube.com/shorts/UqTGI9SMVUI","Link") -> Link | I31: Puxada alta com pegada neutra ou triângulo
C32: Feeder Set 2 | D32: =IF(ISNUMBER($B$34),IF(OR($J$34="",$J$34=0),$B$34*0.85,ROUNDDOWN($B$34*0.85/$J$34,0)*$J$34),"") | E32: 3 - 5 | I32: Equipamento | J32: Polia
B33: Carga de Trabalho | C33: Working Set 1 | D33: =IF(ISNUMBER($B$34),IF(OR($J$34="",$J$34=0),$B$34*1,ROUNDDOWN($B$34*1/$J$34,0)*$J$34),"") | E33: 8 | I33: Como registrar | J33: Visor / pilha
C34: Top Set | D34: =IF(ISNUMBER($B$34),IF(OR($J$34="",$J$34=0),$B$34*1.1,ROUNDDOWN($B$34*1.1/$J$34,0)*$J$34),"") | E34: 6 - 8 | I34: Incremento (kg) | K34: Descanso (s)
I35: Incremento vazio: cálculo exato. Preenchido: arredonda para baixo.
I36: PDF, p. 19. Descanso não especificado no original.
B37: Escolha pegada neutra ou triângulo.
B39: Desenvolvimento na máquina articulada | C39: Feeder Set 1 | D39: =IF(ISNUMBER($B$42),IF(OR($J$42="",$J$42=0),$B$42*0.85,ROUNDDOWN($B$42*0.85/$J$42,0)*$J$42),"") | E39: 3 - 5 | G39: =HYPERLINK("https://www.youtube.com/watch?si=ztY_PX-u_GUjYjy8&v=MleuQl3OPgo&feature=youtu.be","Link") -> Link | I39: Desenvolvimento na máquina articulada
C40: Working Set 1 | D40: =IF(ISNUMBER($B$42),IF(OR($J$42="",$J$42=0),$B$42*1,ROUNDDOWN($B$42*1/$J$42,0)*$J$42),"") | E40: 8 | I40: Equipamento | J40: Halter
B41: Carga de Trabalho | C41: Working Set 2 | D41: =IF(ISNUMBER($B$42),IF(OR($J$42="",$J$42=0),$B$42*1,ROUNDDOWN($B$42*1/$J$42,0)*$J$42),"") | E41: 8 | I41: Como registrar | J41: Visor / pilha
C42: Working Set 3 | D42: =IF(ISNUMBER($B$42),IF(OR($J$42="",$J$42=0),$B$42*1,ROUNDDOWN($B$42*1/$J$42,0)*$J$42),"") | E42: 8 | I42: Incremento (kg) | K42: Descanso (s)
I43: Incremento vazio: cálculo exato. Preenchido: arredonda para baixo.
I44: PDF, p. 19. Descanso não especificado no original.
B45: Alternativa do PDF: smith com banco em 75º.
...

Sheet S1 A3
B1: WELLNESS • SEMANA 1 • A3 | I1: Parâmetros editáveis
B3: Sexta-feira — Pernas e glúteos II | I3: Configure o registro e o incremento conforme o equipamento. Nenhuma carga inicial é presumida.
B4: Preencha a carga de trabalho e as repetições realizadas. Cargas em kg.
B5: Exercício | C5: Série | D5: Cargas | E5: Rep Range | F5: Reps | G5: Vídeo
B6: Cadeira abdutora | C6: Aquecimento | D6: =IF(ISNUMBER($B$9),IF(OR($J$9="",$J$9=0),$B$9*0.3,ROUNDDOWN($B$9*0.3/$J$9,0)*$J$9),"") -> 1.5 | E6: 10 - 15 | G6: =HYPERLINK("https://www.youtube.com/shorts/S9OtoSJdMWo","Link") -> Link | I6: Cadeira abdutora
C7: Feeder Set 1 | D7: =IF(ISNUMBER($B$9),IF(OR($J$9="",$J$9=0),$B$9*0.7,ROUNDDOWN($B$9*0.7/$J$9,0)*$J$9),"") -> 3.5 | E7: 3 - 5 | I7: Equipamento | J7: Máquina
B8: Carga de Trabalho | C8: Feeder Set 2 | D8: =IF(ISNUMBER($B$9),IF(OR($J$9="",$J$9=0),$B$9*0.85,ROUNDDOWN($B$9*0.85/$J$9,0)*$J$9),"") -> 4.25 | E8: 3 - 5 | I8: Como registrar | J8: Visor / pilha
B9: 5 | C9: Working Set 1 | D9: =IF(ISNUMBER($B$9),IF(OR($J$9="",$J$9=0),$B$9*1,ROUNDDOWN($B$9*1/$J$9,0)*$J$9),"") -> 5 | E9: 8 - 12 | I9: Incremento (kg) | K9: Descanso (s)
C10: Working Set 2 | D10: =IF(ISNUMBER($B$9),IF(OR($J$9="",$J$9=0),$B$9*1,ROUNDDOWN($B$9*1/$J$9,0)*$J$9),"") -> 5 | E10: 8 - 12 | I10: Incremento vazio: cálculo exato. Preenchido: arredonda para baixo.
C11: Working Set 3 | D11: =IF(ISNUMBER($B$9),IF(OR($J$9="",$J$9=0),$B$9*1,ROUNDDOWN($B$9*1/$J$9,0)*$J$9),"") -> 5 | E11: 8 - 12 | I11: PDF, p. 20. Descanso não especificado no original.
B12: Tronco levemente inclinado para frente. Aquecimento: 30% da WS, referência da PURGE; o PDF não define percentual.
B14: Elevação pélvica no smith, máquina ou livre | C14: Feeder Set 1 | D14: =IF(ISNUMBER($B$17),IF(OR($J$17="",$J$17=0),$B$17*0.7,ROUNDDOWN($B$17*0.7/$J$17,0)*$J$17),"") | E14: 3 - 5 | G14: =HYPERLINK("https://www.youtube.com/shorts/taUhr2s8Sf0","Link") -> Link | I14: Elevação pélvica no smith, máquina ou livre
C15: Feeder Set 2 | D15: =IF(ISNUMBER($B$17),IF(OR($J$17="",$J$17=0),$B$17*0.85,ROUNDDOWN($B$17*0.85/$J$17,0)*$J$17),"") | E15: 3 - 5 | I15: Equipamento | J15: Barra / smith
B16: Carga de Trabalho | C16: Working Set 1 | D16: =IF(ISNUMBER($B$17),IF(OR($J$17="",$J$17=0),$B$17*1,ROUNDDOWN($B$17*1/$J$17,0)*$J$17),"") | E16: 8 | I16: Como registrar | J16: Total com barra
C17: Top Set | D17: =IF(ISNUMBER($B$17),IF(OR($J$17="",$J$17=0),$B$17*1.1,ROUNDDOWN($B$17*1.1/$J$17,0)*$J$17),"") | E17: 6 - 8 | I17: Incremento (kg) | K17: Descanso (s)
I18: Incremento vazio: cálculo exato. Preenchido: arredonda para baixo.
I19: PDF, p. 20. Descanso não especificado no original.
B20: Use band nos joelhos. Escolha uma das opções do PDF.
B22: Leg press 45º | C22: Feeder Set 1 | D22: =IF(ISNUMBER($B$25),IF(OR($J$25="",$J$25=0),$B$25*0.5,ROUNDDOWN($B$25*0.5/$J$25,0)*$J$25),"") | E22: 3 - 5 | G22: =HYPERLINK("https://www.youtube.com/watch?v=hYKoCUczAY4","Link") -> Link | I22: Leg press 45º
C23: Feeder Set 2 | D23: =IF(ISNUMBER($B$25),IF(OR($J$25="",$J$25=0),$B$25*0.7,ROUNDDOWN($B$25*0.7/$J$25,0)*$J$25),"") | E23: 3 - 5 | I23: Equipamento | J23: Máquina
B24: Carga de Trabalho | C24: Feeder Set 3 | D24: =IF(ISNUMBER($B$25),IF(OR($J$25="",$J$25=0),$B$25*0.85,ROUNDDOWN($B$25*0.85/$J$25,0)*$J$25),"") | E24: 3 - 5 | I24: Como registrar | J24: Total de anilhas
C25: Working Set 1 | D25: =IF(ISNUMBER($B$25),IF(OR($J$25="",$J$25=0),$B$25*1,ROUNDDOWN($B$25*1/$J$25,0)*$J$25),"") | E25: 8 | I25: Incremento (kg) | K25: Descanso (s)
C26: Top Set | D26: =IF(ISNUMBER($B$25),IF(OR($J$25="",$J$25=0),$B$25*1.1,ROUNDDOWN($B$25*1.1/$J$25,0)*$J$25),"") | E26: 6 - 8 | I26: Incremento vazio: cálculo exato. Preenchido: arredonda para baixo.
I27: PDF, p. 20. Descanso não especificado no original.
B30: Stiff unilateral | C30: Feeder Set 1 | D30: =IF(ISNUMBER($B$33),IF(OR($J$33="",$J$33=0),$B$33*0.85,ROUNDDOWN($B$33*0.85/$J$33,0)*$J$33),"") | E30: 3 - 5 | G30: =HYPERLINK("https://www.youtube.com/shorts/U3prDlAbJDw","Link") -> Link | I30: Stiff unilateral
C31: Working Set 1 | D31: =IF(ISNUMBER($B$33),IF(OR($J$33="",$J$33=0),$B$33*1,ROUNDDOWN($B$33*1/$J$33,0)*$J$33),"") | E31: 8 | I31: Equipamento | J31: Halter
B32: Carga de Trabalho | C32: Working Set 2 | D32: =IF(ISNUMBER($B$33),IF(OR($J$33="",$J$33=0),$B$33*1,ROUNDDOWN($B$33*1/$J$33,0)*$J$33),"") | E32: 8 | I32: Como registrar | J32: Por halter
I33: Incremento (kg) | K33: Descanso (s)
I34: Incremento vazio: cálculo exato. Preenchido: arredonda para baixo.
I35: PDF, p. 20. Descanso não especificado no original.
B36: Um pé de apoio no chão. Séries e reps por perna.
B46: Treino concluído | F46: Não

Sheet S2 A1
B1: WELLNESS • SEMANA 2 • A1 | I1: Parâmetros editáveis
B3: Segunda-feira — Superiores II | I3: Configure o registro e o incremento conforme o equipamento. Nenhuma carga inicial é presumida.
B4: Preencha a carga de trabalho e as repetições realizadas. Cargas em kg.
B5: Exercício | C5: Série | D5: Cargas | E5: Rep Range | F5: Reps | G5: Vídeo
B6: Elevação lateral com halteres sentada (90º) | C6: Aquecimento | D6: =IF(ISNUMBER($B$9),IF(OR($J$9="",$J$9=0),$B$9*0.3,ROUNDDOWN($B$9*0.3/$J$9,0)*$J$9),"") | E6: 10 - 15 | G6: =HYPERLINK("https://www.youtube.com/shorts/N_K2ZSCvl84","Link") -> Link | I6: Elevação lateral com halteres sentada (90º)
C7: Feeder Set 1 | D7: =IF(ISNUMBER($B$9),IF(OR($J$9="",$J$9=0),$B$9*0.7,ROUNDDOWN($B$9*0.7/$J$9,0)*$J$9),"") | E7: 3 - 5 | I7: Equipamento | J7: Halter
B8: Carga de Trabalho | C8: Feeder Set 2 | D8: =IF(ISNUMBER($B$9),IF(OR($J$9="",$J$9=0),$B$9*0.85,ROUNDDOWN($B$9*0.85/$J$9,0)*$J$9),"") | E8: 3 - 5 | I8: Como registrar | J8: Por halter
C9: Working Set 1 | D9: =IF(ISNUMBER($B$9),IF(OR($J$9="",$J$9=0),$B$9*1,ROUNDDOWN($B$9*1/$J$9,0)*$J$9),"") | E9: 8 - 12 | I9: Incremento (kg) | K9: Descanso (s)
C10: Working Set 2 | D10: =IF(ISNUMBER($B$9),IF(OR($J$9="",$J$9=0),$B$9*1,ROUNDDOWN($B$9*1/$J$9,0)*$J$9),"") | E10: 8 - 12 | I10: Incremento vazio: cálculo exato. Preenchido: arredonda para baixo.
C11: Working Set 3 | D11: =IF(ISNUMBER($B$9),IF(OR($J$9="",$J$9=0),$B$9*1,ROUNDDOWN($B$9*1/$J$9,0)*$J$9),"") | E11: 8 - 12 | I11: PDF, p. 21. Descanso não especificado no original.
B12: Banco em 90º. Aquecimento: 30% da WS, referência da PURGE; o PDF não define percentual.
B14: Remada baixa na polia com barra reta | C14: Feeder Set 1 | D14: =IF(ISNUMBER($B$17),IF(OR($J$17="",$J$17=0),$B$17*0.7,ROUNDDOWN($B$17*0.7/$J$17,0)*$J$17),"") | E14: 3 - 5 | G14: =HYPERLINK("https://www.youtube.com/watch?v=yVGjnrMeSyU","Link") -> Link | I14: Remada baixa na polia com barra reta
C15: Feeder Set 2 | D15: =IF(ISNUMBER($B$17),IF(OR($J$17="",$J$17=0),$B$17*0.85,ROUNDDOWN($B$17*0.85/$J$17,0)*$J$17),"") | E15: 3 - 5 | I15: Equipamento | J15: Polia
B16: Carga de Trabalho | C16: Working Set 1 | D16: =IF(ISNUMBER($B$17),IF(OR($J$17="",$J$17=0),$B$17*1,ROUNDDOWN($B$17*1/$J$17,0)*$J$17),"") | E16: 8 | I16: Como registrar | J16: Visor / pilha
C17: Top Set | D17: =IF(ISNUMBER($B$17),IF(OR($J$17="",$J$17=0),$B$17*1.1,ROUNDDOWN($B$17*1.1/$J$17,0)*$J$17),"") | E17: 6 - 8 | I17: Incremento (kg) | K17: Descanso (s)
I18: Incremento vazio: cálculo exato. Preenchido: arredonda para baixo.
I19: PDF, p. 21. Descanso não especificado no original.
B20: Pegada pronada.
B22: Remada articulada unilateral | C22: Feeder Set 1 | D22: =IF(ISNUMBER($B$25),IF(OR($J$25="",$J$25=0),$B$25*0.85,ROUNDDOWN($B$25*0.85/$J$25,0)*$J$25),"") | E22: 3 - 5 | G22: =HYPERLINK("https://www.youtube.com/watch?v=gnKmUlTOaCw","Link") -> Link | I22: Remada articulada unilateral
C23: Working Set 1 | D23: =IF(ISNUMBER($B$25),IF(OR($J$25="",$J$25=0),$B$25*1,ROUNDDOWN($B$25*1/$J$25,0)*$J$25),"") | E23: 8 | I23: Equipamento | J23: Máquina
B24: Carga de Trabalho | C24: Top Set | D24: =IF(ISNUMBER($B$25),IF(OR($J$25="",$J$25=0),$B$25*1.1,ROUNDDOWN($B$25*1.1/$J$25,0)*$J$25),"") | E24: 6 - 8 | I24: Como registrar | J24: Por lado
I25: Incremento (kg) | K25: Descanso (s)
I26: Incremento vazio: cálculo exato. Preenchido: arredonda para baixo.
I27: PDF, p. 21. Descanso não especificado no original.
B28: Séries e reps por lado.
B30: Elevação lateral na polia | C30: Feeder Set 1 | D30: =IF(ISNUMBER($B$33),IF(OR($J$33="",$J$33=0),$B$33*0.85,ROUNDDOWN($B$33*0.85/$J$33,0)*$J$33),"") | E30: 3 - 5 | G30: =HYPERLINK("https://www.youtube.com/watch?v=BH9jVp2cx3w","Link") -> Link | I30: Elevação lateral na polia
C31: Working Set 1 | D31: =IF(ISNUMBER($B$33),IF(OR($J$33="",$J$33=0),$B$33*1,ROUNDDOWN($B$33*1/$J$33,0)*$J$33),"") | E31: 8 - 12 | I31: Equipamento | J31: Polia
B32: Carga de Trabalho | C32: Working Set 2 | D32: =IF(ISNUMBER($B$33),IF(OR($J$33="",$J$33=0),$B$33*1,ROUNDDOWN($B$33*1/$J$33,0)*$J$33),"") | E32: 8 - 12 | I32: Como registrar | J32: Visor / pilha
C33: Working Set 3 | D33: =IF(ISNUMBER($B$33),IF(OR($J$33="",$J$33=0),$B$33*1,ROUNDDOWN($B$33*1/$J$33,0)*$J$33),"") | E33: 8 - 12 | I33: Incremento (kg) | K33: Descanso (s)
I34: Incremento vazio: cálculo exato. Preenchido: arredonda para baixo.
I35: PDF, p. 21. Descanso não especificado no original.
B36: Braços esticados, levemente à frente do tronco. Séries e reps por lado.
B38: Tríceps na polia alta com barra reta ou V | C38: Feeder Set 1 | D38: =IF(ISNUMBER($B$41),IF(OR($J$41="",$J$41=0),$B$41*0.85,ROUNDDOWN($B$41*0.85/$J$41,0)*$J$41),"") | E38: 3 - 5 | G38: =HYPERLINK("https://www.youtube.com/watch?v=9cmeOVHOjck","Link") -> Link | I38: Tríceps na polia alta com barra reta ou V
C39: Working Set 1 | D39: =IF(ISNUMBER($B$41),IF(OR($J$41="",$J$41=0),$B$41*1,ROUNDDOWN($B$41*1/$J$41,0)*$J$41),"") | E39: 8 - 12 | I39: Equipamento | J39: Polia
B40: Carga de Trabalho | C40: Working Set 2 | D40: =IF(ISNUMBER($B$41),IF(OR($J$41="",$J$41=0),$B$41*1,ROUNDDOWN($B$41*1/$J$41,0)*$J$41),"") | E40: 8 - 12 | I40: Como registrar | J40: Visor / pilha
C41: Working Set 3 | D41: =IF(ISNUMBER($B$41),IF(OR($J$41="",$J$41=0),$B$41*1,ROUNDDOWN($B$41*1/$J$41,0)*$J$41),"") | E41: 8 - 12 | I41: Incremento (kg) | K41: Descanso (s)
I42: Incremento vazio: cálculo exato. Preenchido: arredonda para baixo.
I43: PDF, p. 21. Descanso não especificado no original.
B46: Treino concluído | F46: Não

Sheet S2 A2
B1: WELLNESS • SEMANA 2 • A2 | I1: Parâmetros editáveis
B3: Quarta-feira — Pernas e glúteos III | I3: Configure o registro e o incremento conforme o equipamento. Nenhuma carga inicial é presumida.
B4: Preencha a carga de trabalho e as repetições realizadas. Cargas em kg.
B5: Exercício | C5: Série | D5: Cargas | E5: Rep Range | F5: Reps | G5: Vídeo
B6: Cadeira abdutora | C6: Aquecimento | D6: =IF(ISNUMBER($B$9),IF(OR($J$9="",$J$9=0),$B$9*0.3,ROUNDDOWN($B$9*0.3/$J$9,0)*$J$9),"") -> 1.5 | E6: 10 - 15 | G6: =HYPERLINK("https://www.youtube.com/shorts/S9OtoSJdMWo","Link") -> Link | I6: Cadeira abdutora
C7: Working Set 1 | D7: =IF(ISNUMBER($B$9),IF(OR($J$9="",$J$9=0),$B$9*1,ROUNDDOWN($B$9*1/$J$9,0)*$J$9),"") -> 5 | E7: 8 - 12 | I7: Equipamento | J7: Máquina
B8: Carga de Trabalho | C8: Working Set 2 | D8: =IF(ISNUMBER($B$9),IF(OR($J$9="",$J$9=0),$B$9*1,ROUNDDOWN($B$9*1/$J$9,0)*$J$9),"") -> 5 | E8: 8 - 12 | I8: Como registrar | J8: Visor / pilha
B9: 5 | C9: Working Set 3 | D9: =IF(ISNUMBER($B$9),IF(OR($J$9="",$J$9=0),$B$9*1,ROUNDDOWN($B$9*1/$J$9,0)*$J$9),"") -> 5 | E9: 8 - 12 | I9: Incremento (kg) | K9: Descanso (s)
I10: Incremento vazio: cálculo exato. Preenchido: arredonda para baixo.
I11: PDF, p. 23. Descanso não especificado no original.
B12: Tronco levemente inclinado para frente. Aquecimento: 30% da WS, referência da PURGE; o PDF não define percentual.
B14: Cadeira flexora | C14: Feeder Set 1 | D14: =IF(ISNUMBER($B$17),IF(OR($J$17="",$J$17=0),$B$17*0.7,ROUNDDOWN($B$17*0.7/$J$17,0)*$J$17),"") | E14: 3 - 5 | G14: =HYPERLINK("https://www.youtube.com/watch?v=wqVoX6lbYf8","Link") -> Link | I14: Cadeira flexora
C15: Feeder Set 2 | D15: =IF(ISNUMBER($B$17),IF(OR($J$17="",$J$17=0),$B$17*0.85,ROUNDDOWN($B$17*0.85/$J$17,0)*$J$17),"") | E15: 3 - 5 | I15: Equipamento | J15: Máquina
B16: Carga de Trabalho | C16: Working Set 1 | D16: =IF(ISNUMBER($B$17),IF(OR($J$17="",$J$17=0),$B$17*1,ROUNDDOWN($B$17*1/$J$17,0)*$J$17),"") | E16: 8 | I16: Como registrar | J16: Visor / pilha
C17: Top Set | D17: =IF(ISNUMBER($B$17),IF(OR($J$17="",$J$17=0),$B$17*1.1,ROUNDDOWN($B$17*1.1/$J$17,0)*$J$17),"") | E17: 6 - 8 | I17: Incremento (kg) | K17: Descanso (s)
I18: Incremento vazio: cálculo exato. Preenchido: arredonda para baixo.
I19: Exercício adaptado. Séries e repetições do exercício substituído.
B20: Cadeira flexora sentada. Ajuste banco e apoios do aparelho.
B22: Terra sumô | C22: Feeder Set 1 | D22: =IF(ISNUMBER($B$25),IF(OR($J$25="",$J$25=0),$B$25*0.5,ROUNDDOWN($B$25*0.5/$J$25,0)*$J$25),"") | E22: 3 | G22: =HYPERLINK("https://www.youtube.com/watch?v=pfSMst14EFk","Link") -> Link | I22: Terra sumô
C23: Feeder Set 2 | D23: =IF(ISNUMBER($B$25),IF(OR($J$25="",$J$25=0),$B$25*0.7,ROUNDDOWN($B$25*0.7/$J$25,0)*$J$25),"") | E23: 3 | I23: Equipamento | J23: Barra / smith
B24: Carga de Trabalho | C24: Feeder Set 3 | D24: =IF(ISNUMBER($B$25),IF(OR($J$25="",$J$25=0),$B$25*0.85,ROUNDDOWN($B$25*0.85/$J$25,0)*$J$25),"") | E24: 3 | I24: Como registrar | J24: Total com barra
C25: Working Set 1 | D25: =IF(ISNUMBER($B$25),IF(OR($J$25="",$J$25=0),$B$25*1,ROUNDDOWN($B$25*1/$J$25,0)*$J$25),"") | E25: 5 | I25: Incremento (kg) | K25: Descanso (s)
C26: Working Set 2 | D26: =IF(ISNUMBER($B$25),IF(OR($J$25="",$J$25=0),$B$25*1,ROUNDDOWN($B$25*1/$J$25,0)*$J$25),"") | E26: 5 | I26: Incremento vazio: cálculo exato. Preenchido: arredonda para baixo.
I27: PDF, p. 23. Descanso não especificado no original.
B30: Elevação pélvica no smith, máquina ou livre | C30: Feeder Set 1 | D30: =IF(ISNUMBER($B$33),IF(OR($J$33="",$J$33=0),$B$33*0.7,ROUNDDOWN($B$33*0.7/$J$33,0)*$J$33),"") | E30: 3 | G30: =HYPERLINK("https://www.youtube.com/shorts/taUhr2s8Sf0","Link") -> Link | I30: Elevação pélvica no smith, máquina ou livre
C31: Feeder Set 2 | D31: =IF(ISNUMBER($B$33),IF(OR($J$33="",$J$33=0),$B$33*0.85,ROUNDDOWN($B$33*0.85/$J$33,0)*$J$33),"") | E31: 3 | I31: Equipamento | J31: Barra / smith
B32: Carga de Trabalho | C32: Working Set 1 | D32: =IF(ISNUMBER($B$33),IF(OR($J$33="",$J$33=0),$B$33*1,ROUNDDOWN($B$33*1/$J$33,0)*$J$33),"") | E32: 8 | I32: Como registrar | J32: Total com barra
C33: Working Set 2 | D33: =IF(ISNUMBER($B$33),IF(OR($J$33="",$J$33=0),$B$33*1,ROUNDDOWN($B$33*1/$J$33,0)*$J$33),"") | E33: 8 | I33: Incremento (kg) | K33: Descanso (s)
I34: Incremento vazio: cálculo exato. Preenchido: arredonda para baixo.
I35: PDF, p. 23. Descanso não especificado no original.
B36: Use band nos joelhos. Escolha uma das opções do PDF.
B38: Abdução de quadril na polia | C38: Feeder Set 1 | D38: =IF(ISNUMBER($B$41),IF(OR($J$41="",$J$41=0),$B$41*0.7,ROUNDDOWN($B$41*0.7/$J$41,0)*$J$41),"") | E38: 3 - 5 | G38: =HYPERLINK("https://www.youtube.com/watch?v=hQOfjxHnRvg","Link") -> Link | I38: Abdução de quadril na polia
C39: Feeder Set 2 | D39: =IF(ISNUMBER($B$41),IF(OR($J$41="",$J$41=0),$B$41*0.85,ROUNDDOWN($B$41*0.85/$J$41,0)*$J$41),"") | E39: 3 - 5 | I39: Equipamento | J39: Polia
B40: Carga de Trabalho | C40: Working Set 1 | D40: =IF(ISNUMBER($B$41),IF(OR($J$41="",$J$41=0),$B$41*1,ROUNDDOWN($B$41*1/$J$41,0)*$J$41),"") | E40: 8 - 12 | I40: Como registrar | J40: Visor / pilha
C41: Working Set 2 | D41: =IF(ISNUMBER($B$41),IF(OR($J$41="",$J$41=0),$B$41*1,ROUNDDOWN($B$41*1/$J$41,0)*$J$41),"") | E41: 8 - 12 | I41: Incremento (kg) | K41: Descanso (s)
C42: Working Set 3 | D42: =IF(ISNUMBER($B$41),IF(OR($J$41="",$J$41=0),$B$41*1,ROUNDDOWN($B$41*1/$J$41,0)*$J$41),"") | E42: 8 - 12 | I42: Incremento vazio: cálculo exato. Preenchido: arredonda para baixo.
I43: PDF, p. 23. Descanso não especificado no original.
B44: Séries e reps por perna.
B46: Cadeira extensora | C46: Feeder Set 1 | D46: =IF(ISNUMBER($B$49),IF(OR($J$49="",$J$49=0),$B$49*0.7,ROUNDDOWN($B$49*0.7/$J$49,0)*$J$49),"") | E46: 3 - 5 | G46: =HYPERLINK("https://www.youtube.com/watch?v=m0FOpMEgero","Link") -> Link | I46: Cadeira extensora
C47: Feeder Set 2 | D47: =IF(ISNUMBER($B$49),IF(OR($J$49="",$J$49=0),$B$49*0.85,ROUNDDOWN($B$49*0.85/$J$49,0)*$J$49),"") | E47: 3 - 5 | I47: Equipamento | J47: Máquina
...

Sheet S2 A3
B1: WELLNESS • SEMANA 2 • A3 | I1: Parâmetros editáveis
B3: Sexta-feira — Superiores I | I3: Configure o registro e o incremento conforme o equipamento. Nenhuma carga inicial é presumida.
B4: Preencha a carga de trabalho e as repetições realizadas. Cargas em kg.
B5: Exercício | C5: Série | D5: Cargas | E5: Rep Range | F5: Reps | G5: Vídeo
B6: Supino inclinado na máquina | C6: Aquecimento | D6: =IF(ISNUMBER($B$9),IF(OR($J$9="",$J$9=0),$B$9*0.3,ROUNDDOWN($B$9*0.3/$J$9,0)*$J$9),"") | E6: 10 - 15 | G6: =HYPERLINK("https://www.youtube.com/watch?v=TrTSvn5-MTk","Link") -> Link | I6: Supino inclinado na máquina
C7: Feeder Set 1 | D7: =IF(ISNUMBER($B$9),IF(OR($J$9="",$J$9=0),$B$9*0.5,ROUNDDOWN($B$9*0.5/$J$9,0)*$J$9),"") | E7: 3 | I7: Equipamento | J7: Máquina
B8: Carga de Trabalho | C8: Feeder Set 2 | D8: =IF(ISNUMBER($B$9),IF(OR($J$9="",$J$9=0),$B$9*0.7,ROUNDDOWN($B$9*0.7/$J$9,0)*$J$9),"") | E8: 3 | I8: Como registrar | J8: Visor / pilha
C9: Feeder Set 3 | D9: =IF(ISNUMBER($B$9),IF(OR($J$9="",$J$9=0),$B$9*0.85,ROUNDDOWN($B$9*0.85/$J$9,0)*$J$9),"") | E9: 3 | I9: Incremento (kg) | K9: Descanso (s)
C10: Working Set 1 | D10: =IF(ISNUMBER($B$9),IF(OR($J$9="",$J$9=0),$B$9*1,ROUNDDOWN($B$9*1/$J$9,0)*$J$9),"") | E10: 8 | I10: Incremento vazio: cálculo exato. Preenchido: arredonda para baixo.
C11: Top Set | D11: =IF(ISNUMBER($B$9),IF(OR($J$9="",$J$9=0),$B$9*1.1,ROUNDDOWN($B$9*1.1/$J$9,0)*$J$9),"") | E11: 6 - 8 | I11: PDF, p. 19. Descanso não especificado no original.
C12: Back Off | D12: =IF(ISNUMBER($B$9),IF(OR($J$9="",$J$9=0),$B$9*0.75,ROUNDDOWN($B$9*0.75/$J$9,0)*$J$9),"") | E12: 8 - 12
B13: Alternativa do PDF: halteres no banco em 30º. Aquecimento: 30% da WS, referência da PURGE; o PDF não define percentual.
B15: Elevação lateral com halteres sentada | C15: Feeder Set 1 | D15: =IF(ISNUMBER($B$18),IF(OR($J$18="",$J$18=0),$B$18*0.7,ROUNDDOWN($B$18*0.7/$J$18,0)*$J$18),"") | E15: 3 | G15: =HYPERLINK("https://www.youtube.com/shorts/Qy-zXcgZHWU","Link") -> Link | I15: Elevação lateral com halteres sentada
C16: Feeder Set 2 | D16: =IF(ISNUMBER($B$18),IF(OR($J$18="",$J$18=0),$B$18*0.85,ROUNDDOWN($B$18*0.85/$J$18,0)*$J$18),"") | E16: 3 | I16: Equipamento | J16: Halter
B17: Carga de Trabalho | C17: Working Set 1 | D17: =IF(ISNUMBER($B$18),IF(OR($J$18="",$J$18=0),$B$18*1,ROUNDDOWN($B$18*1/$J$18,0)*$J$18),"") | E17: 8 - 12 | I17: Como registrar | J17: Por halter
C18: Working Set 2 | D18: =IF(ISNUMBER($B$18),IF(OR($J$18="",$J$18=0),$B$18*1,ROUNDDOWN($B$18*1/$J$18,0)*$J$18),"") | E18: 8 - 12 | I18: Incremento (kg) | K18: Descanso (s)
C19: Working Set 3 | D19: =IF(ISNUMBER($B$18),IF(OR($J$18="",$J$18=0),$B$18*1,ROUNDDOWN($B$18*1/$J$18,0)*$J$18),"") | E19: 8 - 12 | I19: Incremento vazio: cálculo exato. Preenchido: arredonda para baixo.
I20: PDF, p. 19. Descanso não especificado no original.
B21: Braços esticados, levemente à frente do tronco.
B23: Remada articulada unilateral | C23: Feeder Set 1 | D23: =IF(ISNUMBER($B$26),IF(OR($J$26="",$J$26=0),$B$26*0.7,ROUNDDOWN($B$26*0.7/$J$26,0)*$J$26),"") | E23: 3 - 5 | G23: =HYPERLINK("https://www.youtube.com/watch?v=gnKmUlTOaCw","Link") -> Link | I23: Remada articulada unilateral
C24: Feeder Set 2 | D24: =IF(ISNUMBER($B$26),IF(OR($J$26="",$J$26=0),$B$26*0.85,ROUNDDOWN($B$26*0.85/$J$26,0)*$J$26),"") | E24: 3 - 5 | I24: Equipamento | J24: Máquina
B25: Carga de Trabalho | C25: Working Set 1 | D25: =IF(ISNUMBER($B$26),IF(OR($J$26="",$J$26=0),$B$26*1,ROUNDDOWN($B$26*1/$J$26,0)*$J$26),"") | E25: 8 | I25: Como registrar | J25: Por lado
C26: Top Set | D26: =IF(ISNUMBER($B$26),IF(OR($J$26="",$J$26=0),$B$26*1.1,ROUNDDOWN($B$26*1.1/$J$26,0)*$J$26),"") | E26: 6 - 8 | I26: Incremento (kg) | K26: Descanso (s)
I27: Incremento vazio: cálculo exato. Preenchido: arredonda para baixo.
I28: PDF, p. 19. Descanso não especificado no original.
B29: Séries e reps por lado.
B31: Puxada alta com pegada neutra ou triângulo | C31: Feeder Set 1 | D31: =IF(ISNUMBER($B$34),IF(OR($J$34="",$J$34=0),$B$34*0.7,ROUNDDOWN($B$34*0.7/$J$34,0)*$J$34),"") | E31: 3 - 5 | G31: =HYPERLINK("https://www.youtube.com/shorts/UqTGI9SMVUI","Link") -> Link | I31: Puxada alta com pegada neutra ou triângulo
C32: Feeder Set 2 | D32: =IF(ISNUMBER($B$34),IF(OR($J$34="",$J$34=0),$B$34*0.85,ROUNDDOWN($B$34*0.85/$J$34,0)*$J$34),"") | E32: 3 - 5 | I32: Equipamento | J32: Polia
B33: Carga de Trabalho | C33: Working Set 1 | D33: =IF(ISNUMBER($B$34),IF(OR($J$34="",$J$34=0),$B$34*1,ROUNDDOWN($B$34*1/$J$34,0)*$J$34),"") | E33: 8 | I33: Como registrar | J33: Visor / pilha
C34: Top Set | D34: =IF(ISNUMBER($B$34),IF(OR($J$34="",$J$34=0),$B$34*1.1,ROUNDDOWN($B$34*1.1/$J$34,0)*$J$34),"") | E34: 6 - 8 | I34: Incremento (kg) | K34: Descanso (s)
I35: Incremento vazio: cálculo exato. Preenchido: arredonda para baixo.
I36: PDF, p. 19. Descanso não especificado no original.
B37: Escolha pegada neutra ou triângulo.
B39: Desenvolvimento na máquina articulada | C39: Feeder Set 1 | D39: =IF(ISNUMBER($B$42),IF(OR($J$42="",$J$42=0),$B$42*0.85,ROUNDDOWN($B$42*0.85/$J$42,0)*$J$42),"") | E39: 3 - 5 | G39: =HYPERLINK("https://www.youtube.com/watch?si=ztY_PX-u_GUjYjy8&v=MleuQl3OPgo&feature=youtu.be","Link") -> Link | I39: Desenvolvimento na máquina articulada
C40: Working Set 1 | D40: =IF(ISNUMBER($B$42),IF(OR($J$42="",$J$42=0),$B$42*1,ROUNDDOWN($B$42*1/$J$42,0)*$J$42),"") | E40: 8 | I40: Equipamento | J40: Máquina
B41: Carga de Trabalho | C41: Working Set 2 | D41: =IF(ISNUMBER($B$42),IF(OR($J$42="",$J$42=0),$B$42*1,ROUNDDOWN($B$42*1/$J$42,0)*$J$42),"") | E41: 8 | I41: Como registrar | J41: Visor / pilha
C42: Working Set 3 | D42: =IF(ISNUMBER($B$42),IF(OR($J$42="",$J$42=0),$B$42*1,ROUNDDOWN($B$42*1/$J$42,0)*$J$42),"") | E42: 8 | I42: Incremento (kg) | K42: Descanso (s)
I43: Incremento vazio: cálculo exato. Preenchido: arredonda para baixo.
I44: PDF, p. 19. Descanso não especificado no original.
B45: Alternativa do PDF: smith com banco em 75º.
...

Sheet S3 A1
B1: WELLNESS • SEMANA 3 • A1 | I1: Parâmetros editáveis
B3: Segunda-feira — Pernas e glúteos I | I3: Configure o registro e o incremento conforme o equipamento. Nenhuma carga inicial é presumida.
B4: Preencha a carga de trabalho e as repetições realizadas. Cargas em kg.
B5: Exercício | C5: Série | D5: Cargas | E5: Rep Range | F5: Reps | G5: Vídeo
B6: Cadeira abdutora | C6: Aquecimento | D6: =IF(ISNUMBER($B$9),IF(OR($J$9="",$J$9=0),$B$9*0.3,ROUNDDOWN($B$9*0.3/$J$9,0)*$J$9),"") -> 1.5 | E6: 10 - 15 | G6: =HYPERLINK("https://www.youtube.com/shorts/S9OtoSJdMWo","Link") -> Link | I6: Cadeira abdutora
C7: Feeder Set 1 | D7: =IF(ISNUMBER($B$9),IF(OR($J$9="",$J$9=0),$B$9*0.7,ROUNDDOWN($B$9*0.7/$J$9,0)*$J$9),"") -> 3.5 | E7: 3 - 5 | I7: Equipamento | J7: Máquina
B8: Carga de Trabalho | C8: Feeder Set 2 | D8: =IF(ISNUMBER($B$9),IF(OR($J$9="",$J$9=0),$B$9*0.85,ROUNDDOWN($B$9*0.85/$J$9,0)*$J$9),"") -> 4.25 | E8: 3 - 5 | I8: Como registrar | J8: Visor / pilha
B9: 5 | C9: Working Set 1 | D9: =IF(ISNUMBER($B$9),IF(OR($J$9="",$J$9=0),$B$9*1,ROUNDDOWN($B$9*1/$J$9,0)*$J$9),"") -> 5 | E9: 8 - 12 | I9: Incremento (kg) | K9: Descanso (s)
C10: Working Set 2 | D10: =IF(ISNUMBER($B$9),IF(OR($J$9="",$J$9=0),$B$9*1,ROUNDDOWN($B$9*1/$J$9,0)*$J$9),"") -> 5 | E10: 8 - 12 | I10: Incremento vazio: cálculo exato. Preenchido: arredonda para baixo.
C11: Working Set 3 | D11: =IF(ISNUMBER($B$9),IF(OR($J$9="",$J$9=0),$B$9*1,ROUNDDOWN($B$9*1/$J$9,0)*$J$9),"") -> 5 | E11: 8 - 12 | I11: PDF, p. 26. Descanso não especificado no original.
B12: Tronco levemente inclinado para frente. Aquecimento: 30% da WS, referência da PURGE; o PDF não define percentual.
B14: Cadeira flexora | C14: Feeder Set 1 | D14: =IF(ISNUMBER($B$17),IF(OR($J$17="",$J$17=0),$B$17*0.7,ROUNDDOWN($B$17*0.7/$J$17,0)*$J$17),"") | E14: 3 - 5 | G14: =HYPERLINK("https://www.youtube.com/watch?v=wqVoX6lbYf8","Link") -> Link | I14: Cadeira flexora
C15: Feeder Set 2 | D15: =IF(ISNUMBER($B$17),IF(OR($J$17="",$J$17=0),$B$17*0.85,ROUNDDOWN($B$17*0.85/$J$17,0)*$J$17),"") | E15: 3 - 5 | I15: Equipamento | J15: Máquina
B16: Carga de Trabalho | C16: Working Set 1 | D16: =IF(ISNUMBER($B$17),IF(OR($J$17="",$J$17=0),$B$17*1,ROUNDDOWN($B$17*1/$J$17,0)*$J$17),"") | E16: 8 | I16: Como registrar | J16: Visor / pilha
C17: Top Set | D17: =IF(ISNUMBER($B$17),IF(OR($J$17="",$J$17=0),$B$17*1.1,ROUNDDOWN($B$17*1.1/$J$17,0)*$J$17),"") | E17: 6 - 8 | I17: Incremento (kg) | K17: Descanso (s)
I18: Incremento vazio: cálculo exato. Preenchido: arredonda para baixo.
I19: PDF, p. 26. Descanso não especificado no original.
B22: Hack squat | C22: Feeder Set 1 | D22: =IF(ISNUMBER($B$25),IF(OR($J$25="",$J$25=0),$B$25*0.5,ROUNDDOWN($B$25*0.5/$J$25,0)*$J$25),"") | E22: 3 - 5 | G22: =HYPERLINK("https://www.youtube.com/watch?v=rYgNArpwE7E","Link") -> Link | I22: Hack squat
C23: Feeder Set 2 | D23: =IF(ISNUMBER($B$25),IF(OR($J$25="",$J$25=0),$B$25*0.7,ROUNDDOWN($B$25*0.7/$J$25,0)*$J$25),"") | E23: 3 - 5 | I23: Equipamento | J23: Máquina
B24: Carga de Trabalho | C24: Feeder Set 3 | D24: =IF(ISNUMBER($B$25),IF(OR($J$25="",$J$25=0),$B$25*0.85,ROUNDDOWN($B$25*0.85/$J$25,0)*$J$25),"") | E24: 3 - 5 | I24: Como registrar | J24: Total de anilhas
C25: Working Set 1 | D25: =IF(ISNUMBER($B$25),IF(OR($J$25="",$J$25=0),$B$25*1,ROUNDDOWN($B$25*1/$J$25,0)*$J$25),"") | E25: 8 | I25: Incremento (kg) | K25: Descanso (s)
C26: Top Set | D26: =IF(ISNUMBER($B$25),IF(OR($J$25="",$J$25=0),$B$25*1.1,ROUNDDOWN($B$25*1.1/$J$25,0)*$J$25),"") | E26: 8 - 12 | I26: Incremento vazio: cálculo exato. Preenchido: arredonda para baixo.
I27: Exercício adaptado. Séries e repetições do exercício substituído.
B28: Hack squat. Ajuste a carga neste equipamento; não copie os quilos do agachamento anterior.
B30: Cadeira extensora | C30: Feeder Set 1 | D30: =IF(ISNUMBER($B$33),IF(OR($J$33="",$J$33=0),$B$33*0.7,ROUNDDOWN($B$33*0.7/$J$33,0)*$J$33),"") | E30: 3 - 5 | G30: =HYPERLINK("https://www.youtube.com/watch?v=m0FOpMEgero","Link") -> Link | I30: Cadeira extensora
C31: Feeder Set 2 | D31: =IF(ISNUMBER($B$33),IF(OR($J$33="",$J$33=0),$B$33*0.85,ROUNDDOWN($B$33*0.85/$J$33,0)*$J$33),"") | E31: 3 - 5 | I31: Equipamento | J31: Máquina
B32: Carga de Trabalho | C32: Working Set 1 | D32: =IF(ISNUMBER($B$33),IF(OR($J$33="",$J$33=0),$B$33*1,ROUNDDOWN($B$33*1/$J$33,0)*$J$33),"") | E32: 8 | I32: Como registrar | J32: Visor / pilha
C33: Top Set | D33: =IF(ISNUMBER($B$33),IF(OR($J$33="",$J$33=0),$B$33*1.1,ROUNDDOWN($B$33*1.1/$J$33,0)*$J$33),"") | E33: 6 - 8 | I33: Incremento (kg) | K33: Descanso (s)
I34: Incremento vazio: cálculo exato. Preenchido: arredonda para baixo.
I35: PDF, p. 26. Descanso não especificado no original.
B38: Leg press unilateral | C38: Feeder Set 1 | D38: =IF(ISNUMBER($B$41),IF(OR($J$41="",$J$41=0),$B$41*0.85,ROUNDDOWN($B$41*0.85/$J$41,0)*$J$41),"") | E38: 3 - 5 | G38: =HYPERLINK("https://www.youtube.com/watch?v=9-JxC8XYqcI","Link") -> Link | I38: Leg press unilateral
C39: Working Set 1 | D39: =IF(ISNUMBER($B$41),IF(OR($J$41="",$J$41=0),$B$41*1,ROUNDDOWN($B$41*1/$J$41,0)*$J$41),"") | E39: 8 | I39: Equipamento | J39: Máquina
B40: Carga de Trabalho | C40: Top Set | D40: =IF(ISNUMBER($B$41),IF(OR($J$41="",$J$41=0),$B$41*1.1,ROUNDDOWN($B$41*1.1/$J$41,0)*$J$41),"") | E40: 6 - 8 | I40: Como registrar | J40: Por lado
I41: Incremento (kg) | K41: Descanso (s)
I42: Incremento vazio: cálculo exato. Preenchido: arredonda para baixo.
I43: Exercício adaptado. Séries e repetições do exercício substituído.
B44: Séries e repetições por perna. Registre a carga usada no aparelho para executar com uma perna.
B46: Elevação pélvica no smith, máquina ou livre | C46: Feeder Set 1 | D46: =IF(ISNUMBER($B$49),IF(OR($J$49="",$J$49=0),$B$49*0.85,ROUNDDOWN($B$49*0.85/$J$49,0)*$J$49),"") | E46: 3 - 5 | G46: =HYPERLINK("https://www.youtube.com/shorts/taUhr2s8Sf0","Link") -> Link | I46: Elevação pélvica no smith, máquina ou livre
C47: Working Set 1 | D47: =IF(ISNUMBER($B$49),IF(OR($J$49="",$J$49=0),$B$49*1,ROUNDDOWN($B$49*1/$J$49,0)*$J$49),"") | E47: 8 - 12 | I47: Equipamento | J47: Barra / smith
B48: Carga de Trabalho | C48: Working Set 2 | D48: =IF(ISNUMBER($B$49),IF(OR($J$49="",$J$49=0),$B$49*1,ROUNDDOWN($B$49*1/$J$49,0)*$J$49),"") | E48: 8 - 12 | I48: Como registrar | J48: Total com barra
...

Sheet S3 A2
B1: WELLNESS • SEMANA 3 • A2 | I1: Parâmetros editáveis
B3: Quarta-feira — Superiores II | I3: Configure o registro e o incremento conforme o equipamento. Nenhuma carga inicial é presumida.
B4: Preencha a carga de trabalho e as repetições realizadas. Cargas em kg.
B5: Exercício | C5: Série | D5: Cargas | E5: Rep Range | F5: Reps | G5: Vídeo
B6: Elevação lateral com halteres sentada (90º) | C6: Aquecimento | D6: =IF(ISNUMBER($B$9),IF(OR($J$9="",$J$9=0),$B$9*0.3,ROUNDDOWN($B$9*0.3/$J$9,0)*$J$9),"") | E6: 10 - 15 | G6: =HYPERLINK("https://www.youtube.com/shorts/N_K2ZSCvl84","Link") -> Link | I6: Elevação lateral com halteres sentada (90º)
C7: Feeder Set 1 | D7: =IF(ISNUMBER($B$9),IF(OR($J$9="",$J$9=0),$B$9*0.7,ROUNDDOWN($B$9*0.7/$J$9,0)*$J$9),"") | E7: 3 - 5 | I7: Equipamento | J7: Halter
B8: Carga de Trabalho | C8: Feeder Set 2 | D8: =IF(ISNUMBER($B$9),IF(OR($J$9="",$J$9=0),$B$9*0.85,ROUNDDOWN($B$9*0.85/$J$9,0)*$J$9),"") | E8: 3 - 5 | I8: Como registrar | J8: Por halter
C9: Working Set 1 | D9: =IF(ISNUMBER($B$9),IF(OR($J$9="",$J$9=0),$B$9*1,ROUNDDOWN($B$9*1/$J$9,0)*$J$9),"") | E9: 8 - 12 | I9: Incremento (kg) | K9: Descanso (s)
C10: Working Set 2 | D10: =IF(ISNUMBER($B$9),IF(OR($J$9="",$J$9=0),$B$9*1,ROUNDDOWN($B$9*1/$J$9,0)*$J$9),"") | E10: 8 - 12 | I10: Incremento vazio: cálculo exato. Preenchido: arredonda para baixo.
C11: Working Set 3 | D11: =IF(ISNUMBER($B$9),IF(OR($J$9="",$J$9=0),$B$9*1,ROUNDDOWN($B$9*1/$J$9,0)*$J$9),"") | E11: 8 - 12 | I11: PDF, p. 29. Descanso não especificado no original.
B12: Banco em 90º. Aquecimento: 30% da WS, referência da PURGE; o PDF não define percentual.
B14: Remada baixa na polia com barra reta | C14: Feeder Set 1 | D14: =IF(ISNUMBER($B$17),IF(OR($J$17="",$J$17=0),$B$17*0.7,ROUNDDOWN($B$17*0.7/$J$17,0)*$J$17),"") | E14: 3 - 5 | G14: =HYPERLINK("https://www.youtube.com/watch?v=yVGjnrMeSyU","Link") -> Link | I14: Remada baixa na polia com barra reta
C15: Feeder Set 2 | D15: =IF(ISNUMBER($B$17),IF(OR($J$17="",$J$17=0),$B$17*0.85,ROUNDDOWN($B$17*0.85/$J$17,0)*$J$17),"") | E15: 3 - 5 | I15: Equipamento | J15: Polia
B16: Carga de Trabalho | C16: Working Set 1 | D16: =IF(ISNUMBER($B$17),IF(OR($J$17="",$J$17=0),$B$17*1,ROUNDDOWN($B$17*1/$J$17,0)*$J$17),"") | E16: 8 | I16: Como registrar | J16: Visor / pilha
C17: Top Set | D17: =IF(ISNUMBER($B$17),IF(OR($J$17="",$J$17=0),$B$17*1.1,ROUNDDOWN($B$17*1.1/$J$17,0)*$J$17),"") | E17: 6 - 8 | I17: Incremento (kg) | K17: Descanso (s)
I18: Incremento vazio: cálculo exato. Preenchido: arredonda para baixo.
I19: PDF, p. 29. Descanso não especificado no original.
B20: Pegada pronada.
B22: Remada articulada unilateral | C22: Feeder Set 1 | D22: =IF(ISNUMBER($B$25),IF(OR($J$25="",$J$25=0),$B$25*0.85,ROUNDDOWN($B$25*0.85/$J$25,0)*$J$25),"") | E22: 3 - 5 | G22: =HYPERLINK("https://www.youtube.com/watch?v=gnKmUlTOaCw","Link") -> Link | I22: Remada articulada unilateral
C23: Working Set 1 | D23: =IF(ISNUMBER($B$25),IF(OR($J$25="",$J$25=0),$B$25*1,ROUNDDOWN($B$25*1/$J$25,0)*$J$25),"") | E23: 8 | I23: Equipamento | J23: Máquina
B24: Carga de Trabalho | C24: Top Set | D24: =IF(ISNUMBER($B$25),IF(OR($J$25="",$J$25=0),$B$25*1.1,ROUNDDOWN($B$25*1.1/$J$25,0)*$J$25),"") | E24: 6 - 8 | I24: Como registrar | J24: Por lado
I25: Incremento (kg) | K25: Descanso (s)
I26: Incremento vazio: cálculo exato. Preenchido: arredonda para baixo.
I27: PDF, p. 29. Descanso não especificado no original.
B28: Séries e reps por lado.
B30: Elevação lateral na polia | C30: Feeder Set 1 | D30: =IF(ISNUMBER($B$33),IF(OR($J$33="",$J$33=0),$B$33*0.85,ROUNDDOWN($B$33*0.85/$J$33,0)*$J$33),"") | E30: 3 - 5 | G30: =HYPERLINK("https://www.youtube.com/watch?v=BH9jVp2cx3w","Link") -> Link | I30: Elevação lateral na polia
C31: Working Set 1 | D31: =IF(ISNUMBER($B$33),IF(OR($J$33="",$J$33=0),$B$33*1,ROUNDDOWN($B$33*1/$J$33,0)*$J$33),"") | E31: 8 - 12 | I31: Equipamento | J31: Polia
B32: Carga de Trabalho | C32: Working Set 2 | D32: =IF(ISNUMBER($B$33),IF(OR($J$33="",$J$33=0),$B$33*1,ROUNDDOWN($B$33*1/$J$33,0)*$J$33),"") | E32: 8 - 12 | I32: Como registrar | J32: Visor / pilha
C33: Working Set 3 | D33: =IF(ISNUMBER($B$33),IF(OR($J$33="",$J$33=0),$B$33*1,ROUNDDOWN($B$33*1/$J$33,0)*$J$33),"") | E33: 8 - 12 | I33: Incremento (kg) | K33: Descanso (s)
I34: Incremento vazio: cálculo exato. Preenchido: arredonda para baixo.
I35: PDF, p. 29. Descanso não especificado no original.
B36: Braços esticados, levemente à frente do tronco. Séries e reps por lado.
B38: Tríceps na polia alta com barra reta ou V | C38: Feeder Set 1 | D38: =IF(ISNUMBER($B$41),IF(OR($J$41="",$J$41=0),$B$41*0.85,ROUNDDOWN($B$41*0.85/$J$41,0)*$J$41),"") | E38: 3 - 5 | G38: =HYPERLINK("https://www.youtube.com/watch?v=9cmeOVHOjck","Link") -> Link | I38: Tríceps na polia alta com barra reta ou V
C39: Working Set 1 | D39: =IF(ISNUMBER($B$41),IF(OR($J$41="",$J$41=0),$B$41*1,ROUNDDOWN($B$41*1/$J$41,0)*$J$41),"") | E39: 8 - 12 | I39: Equipamento | J39: Polia
B40: Carga de Trabalho | C40: Working Set 2 | D40: =IF(ISNUMBER($B$41),IF(OR($J$41="",$J$41=0),$B$41*1,ROUNDDOWN($B$41*1/$J$41,0)*$J$41),"") | E40: 8 - 12 | I40: Como registrar | J40: Visor / pilha
C41: Working Set 3 | D41: =IF(ISNUMBER($B$41),IF(OR($J$41="",$J$41=0),$B$41*1,ROUNDDOWN($B$41*1/$J$41,0)*$J$41),"") | E41: 8 - 12 | I41: Incremento (kg) | K41: Descanso (s)
I42: Incremento vazio: cálculo exato. Preenchido: arredonda para baixo.
I43: PDF, p. 29. Descanso não especificado no original.
B46: Treino concluído | F46: Não

Sheet S3 A3
B1: WELLNESS • SEMANA 3 • A3 | I1: Parâmetros editáveis
B3: Sexta-feira — Pernas e glúteos II | I3: Configure o registro e o incremento conforme o equipamento. Nenhuma carga inicial é presumida.
B4: Preencha a carga de trabalho e as repetições realizadas. Cargas em kg.
B5: Exercício | C5: Série | D5: Cargas | E5: Rep Range | F5: Reps | G5: Vídeo
B6: Cadeira abdutora | C6: Aquecimento | D6: =IF(ISNUMBER($B$9),IF(OR($J$9="",$J$9=0),$B$9*0.3,ROUNDDOWN($B$9*0.3/$J$9,0)*$J$9),"") -> 1.5 | E6: 10 - 15 | G6: =HYPERLINK("https://www.youtube.com/shorts/S9OtoSJdMWo","Link") -> Link | I6: Cadeira abdutora
C7: Feeder Set 1 | D7: =IF(ISNUMBER($B$9),IF(OR($J$9="",$J$9=0),$B$9*0.7,ROUNDDOWN($B$9*0.7/$J$9,0)*$J$9),"") -> 3.5 | E7: 3 - 5 | I7: Equipamento | J7: Máquina
B8: Carga de Trabalho | C8: Feeder Set 2 | D8: =IF(ISNUMBER($B$9),IF(OR($J$9="",$J$9=0),$B$9*0.85,ROUNDDOWN($B$9*0.85/$J$9,0)*$J$9),"") -> 4.25 | E8: 3 - 5 | I8: Como registrar | J8: Visor / pilha
B9: 5 | C9: Working Set 1 | D9: =IF(ISNUMBER($B$9),IF(OR($J$9="",$J$9=0),$B$9*1,ROUNDDOWN($B$9*1/$J$9,0)*$J$9),"") -> 5 | E9: 8 - 12 | I9: Incremento (kg) | K9: Descanso (s)
C10: Working Set 2 | D10: =IF(ISNUMBER($B$9),IF(OR($J$9="",$J$9=0),$B$9*1,ROUNDDOWN($B$9*1/$J$9,0)*$J$9),"") -> 5 | E10: 8 - 12 | I10: Incremento vazio: cálculo exato. Preenchido: arredonda para baixo.
C11: Working Set 3 | D11: =IF(ISNUMBER($B$9),IF(OR($J$9="",$J$9=0),$B$9*1,ROUNDDOWN($B$9*1/$J$9,0)*$J$9),"") -> 5 | E11: 8 - 12 | I11: PDF, p. 28. Descanso não especificado no original.
B12: Tronco levemente inclinado para frente. Aquecimento: 30% da WS, referência da PURGE; o PDF não define percentual.
B14: Elevação pélvica no smith, máquina ou livre | C14: Feeder Set 1 | D14: =IF(ISNUMBER($B$17),IF(OR($J$17="",$J$17=0),$B$17*0.7,ROUNDDOWN($B$17*0.7/$J$17,0)*$J$17),"") | E14: 3 - 5 | G14: =HYPERLINK("https://www.youtube.com/shorts/taUhr2s8Sf0","Link") -> Link | I14: Elevação pélvica no smith, máquina ou livre
C15: Feeder Set 2 | D15: =IF(ISNUMBER($B$17),IF(OR($J$17="",$J$17=0),$B$17*0.85,ROUNDDOWN($B$17*0.85/$J$17,0)*$J$17),"") | E15: 3 - 5 | I15: Equipamento | J15: Barra / smith
B16: Carga de Trabalho | C16: Working Set 1 | D16: =IF(ISNUMBER($B$17),IF(OR($J$17="",$J$17=0),$B$17*1,ROUNDDOWN($B$17*1/$J$17,0)*$J$17),"") | E16: 8 | I16: Como registrar | J16: Total com barra
C17: Top Set | D17: =IF(ISNUMBER($B$17),IF(OR($J$17="",$J$17=0),$B$17*1.1,ROUNDDOWN($B$17*1.1/$J$17,0)*$J$17),"") | E17: 6 - 8 | I17: Incremento (kg) | K17: Descanso (s)
I18: Incremento vazio: cálculo exato. Preenchido: arredonda para baixo.
I19: PDF, p. 28. Descanso não especificado no original.
B20: Use band nos joelhos. Escolha uma das opções do PDF.
B22: Leg press 45º | C22: Feeder Set 1 | D22: =IF(ISNUMBER($B$25),IF(OR($J$25="",$J$25=0),$B$25*0.5,ROUNDDOWN($B$25*0.5/$J$25,0)*$J$25),"") | E22: 3 - 5 | G22: =HYPERLINK("https://www.youtube.com/watch?v=hYKoCUczAY4","Link") -> Link | I22: Leg press 45º
C23: Feeder Set 2 | D23: =IF(ISNUMBER($B$25),IF(OR($J$25="",$J$25=0),$B$25*0.7,ROUNDDOWN($B$25*0.7/$J$25,0)*$J$25),"") | E23: 3 - 5 | I23: Equipamento | J23: Máquina
B24: Carga de Trabalho | C24: Feeder Set 3 | D24: =IF(ISNUMBER($B$25),IF(OR($J$25="",$J$25=0),$B$25*0.85,ROUNDDOWN($B$25*0.85/$J$25,0)*$J$25),"") | E24: 3 - 5 | I24: Como registrar | J24: Total de anilhas
C25: Working Set 1 | D25: =IF(ISNUMBER($B$25),IF(OR($J$25="",$J$25=0),$B$25*1,ROUNDDOWN($B$25*1/$J$25,0)*$J$25),"") | E25: 8 | I25: Incremento (kg) | K25: Descanso (s)
C26: Top Set | D26: =IF(ISNUMBER($B$25),IF(OR($J$25="",$J$25=0),$B$25*1.1,ROUNDDOWN($B$25*1.1/$J$25,0)*$J$25),"") | E26: 6 - 8 | I26: Incremento vazio: cálculo exato. Preenchido: arredonda para baixo.
I27: PDF, p. 28. Descanso não especificado no original.
B30: Stiff unilateral | C30: Feeder Set 1 | D30: =IF(ISNUMBER($B$33),IF(OR($J$33="",$J$33=0),$B$33*0.7,ROUNDDOWN($B$33*0.7/$J$33,0)*$J$33),"") | E30: 3 - 5 | G30: =HYPERLINK("https://www.youtube.com/shorts/U3prDlAbJDw","Link") -> Link | I30: Stiff unilateral
C31: Feeder Set 2 | D31: =IF(ISNUMBER($B$33),IF(OR($J$33="",$J$33=0),$B$33*0.85,ROUNDDOWN($B$33*0.85/$J$33,0)*$J$33),"") | E31: 3 - 5 | I31: Equipamento | J31: Halter
B32: Carga de Trabalho | C32: Working Set 1 | D32: =IF(ISNUMBER($B$33),IF(OR($J$33="",$J$33=0),$B$33*1,ROUNDDOWN($B$33*1/$J$33,0)*$J$33),"") | E32: 8 | I32: Como registrar | J32: Por halter
C33: Top Set | D33: =IF(ISNUMBER($B$33),IF(OR($J$33="",$J$33=0),$B$33*1.1,ROUNDDOWN($B$33*1.1/$J$33,0)*$J$33),"") | E33: 6 - 8 | I33: Incremento (kg) | K33: Descanso (s)
I34: Incremento vazio: cálculo exato. Preenchido: arredonda para baixo.
I35: PDF, p. 28. Descanso não especificado no original.
B36: Um pé de apoio no chão. Séries e reps por perna.
B46: Treino concluído | F46: Não

Sheet S4 A1
B1: WELLNESS • SEMANA 4 • A1 | I1: Parâmetros editáveis
B3: Segunda-feira — Superiores I | I3: Configure o registro e o incremento conforme o equipamento. Nenhuma carga inicial é presumida.
B4: Preencha a carga de trabalho e as repetições realizadas. Cargas em kg.
B5: Exercício | C5: Série | D5: Cargas | E5: Rep Range | F5: Reps | G5: Vídeo
B6: Supino inclinado na máquina | C6: Aquecimento | D6: =IF(ISNUMBER($B$9),IF(OR($J$9="",$J$9=0),$B$9*0.3,ROUNDDOWN($B$9*0.3/$J$9,0)*$J$9),"") | E6: 10 - 15 | G6: =HYPERLINK("https://www.youtube.com/watch?v=TrTSvn5-MTk","Link") -> Link | I6: Supino inclinado na máquina
C7: Feeder Set 1 | D7: =IF(ISNUMBER($B$9),IF(OR($J$9="",$J$9=0),$B$9*0.5,ROUNDDOWN($B$9*0.5/$J$9,0)*$J$9),"") | E7: 3 | I7: Equipamento | J7: Máquina
B8: Carga de Trabalho | C8: Feeder Set 2 | D8: =IF(ISNUMBER($B$9),IF(OR($J$9="",$J$9=0),$B$9*0.7,ROUNDDOWN($B$9*0.7/$J$9,0)*$J$9),"") | E8: 3 | I8: Como registrar | J8: Visor / pilha
C9: Feeder Set 3 | D9: =IF(ISNUMBER($B$9),IF(OR($J$9="",$J$9=0),$B$9*0.85,ROUNDDOWN($B$9*0.85/$J$9,0)*$J$9),"") | E9: 3 | I9: Incremento (kg) | K9: Descanso (s)
C10: Working Set 1 | D10: =IF(ISNUMBER($B$9),IF(OR($J$9="",$J$9=0),$B$9*1,ROUNDDOWN($B$9*1/$J$9,0)*$J$9),"") | E10: 8 | I10: Incremento vazio: cálculo exato. Preenchido: arredonda para baixo.
C11: Top Set | D11: =IF(ISNUMBER($B$9),IF(OR($J$9="",$J$9=0),$B$9*1.1,ROUNDDOWN($B$9*1.1/$J$9,0)*$J$9),"") | E11: 6 - 8 | I11: PDF, p. 27. Descanso não especificado no original.
C12: Back Off | D12: =IF(ISNUMBER($B$9),IF(OR($J$9="",$J$9=0),$B$9*0.75,ROUNDDOWN($B$9*0.75/$J$9,0)*$J$9),"") | E12: 8 - 12
B13: Alternativa do PDF: halteres no banco em 30º. Aquecimento: 30% da WS, referência da PURGE; o PDF não define percentual.
B15: Elevação lateral com halteres sentada | C15: Feeder Set 1 | D15: =IF(ISNUMBER($B$18),IF(OR($J$18="",$J$18=0),$B$18*0.7,ROUNDDOWN($B$18*0.7/$J$18,0)*$J$18),"") | E15: 3 | G15: =HYPERLINK("https://www.youtube.com/shorts/Qy-zXcgZHWU","Link") -> Link | I15: Elevação lateral com halteres sentada
C16: Feeder Set 2 | D16: =IF(ISNUMBER($B$18),IF(OR($J$18="",$J$18=0),$B$18*0.85,ROUNDDOWN($B$18*0.85/$J$18,0)*$J$18),"") | E16: 3 | I16: Equipamento | J16: Halter
B17: Carga de Trabalho | C17: Working Set 1 | D17: =IF(ISNUMBER($B$18),IF(OR($J$18="",$J$18=0),$B$18*1,ROUNDDOWN($B$18*1/$J$18,0)*$J$18),"") | E17: 8 - 12 | I17: Como registrar | J17: Por halter
C18: Working Set 2 | D18: =IF(ISNUMBER($B$18),IF(OR($J$18="",$J$18=0),$B$18*1,ROUNDDOWN($B$18*1/$J$18,0)*$J$18),"") | E18: 8 - 12 | I18: Incremento (kg) | K18: Descanso (s)
C19: Working Set 3 | D19: =IF(ISNUMBER($B$18),IF(OR($J$18="",$J$18=0),$B$18*1,ROUNDDOWN($B$18*1/$J$18,0)*$J$18),"") | E19: 8 - 12 | I19: Incremento vazio: cálculo exato. Preenchido: arredonda para baixo.
I20: PDF, p. 27. Descanso não especificado no original.
B21: Braços esticados, levemente à frente do tronco.
B23: Remada articulada unilateral | C23: Feeder Set 1 | D23: =IF(ISNUMBER($B$26),IF(OR($J$26="",$J$26=0),$B$26*0.7,ROUNDDOWN($B$26*0.7/$J$26,0)*$J$26),"") | E23: 3 - 5 | G23: =HYPERLINK("https://www.youtube.com/watch?v=gnKmUlTOaCw","Link") -> Link | I23: Remada articulada unilateral
C24: Feeder Set 2 | D24: =IF(ISNUMBER($B$26),IF(OR($J$26="",$J$26=0),$B$26*0.85,ROUNDDOWN($B$26*0.85/$J$26,0)*$J$26),"") | E24: 3 - 5 | I24: Equipamento | J24: Máquina
B25: Carga de Trabalho | C25: Working Set 1 | D25: =IF(ISNUMBER($B$26),IF(OR($J$26="",$J$26=0),$B$26*1,ROUNDDOWN($B$26*1/$J$26,0)*$J$26),"") | E25: 8 | I25: Como registrar | J25: Por lado
C26: Top Set | D26: =IF(ISNUMBER($B$26),IF(OR($J$26="",$J$26=0),$B$26*1.1,ROUNDDOWN($B$26*1.1/$J$26,0)*$J$26),"") | E26: 6 - 8 | I26: Incremento (kg) | K26: Descanso (s)
I27: Incremento vazio: cálculo exato. Preenchido: arredonda para baixo.
I28: PDF, p. 27. Descanso não especificado no original.
B29: Séries e reps por lado.
B31: Puxada alta com pegada neutra ou triângulo | C31: Feeder Set 1 | D31: =IF(ISNUMBER($B$34),IF(OR($J$34="",$J$34=0),$B$34*0.7,ROUNDDOWN($B$34*0.7/$J$34,0)*$J$34),"") | E31: 3 - 5 | G31: =HYPERLINK("https://www.youtube.com/shorts/UqTGI9SMVUI","Link") -> Link | I31: Puxada alta com pegada neutra ou triângulo
C32: Feeder Set 2 | D32: =IF(ISNUMBER($B$34),IF(OR($J$34="",$J$34=0),$B$34*0.85,ROUNDDOWN($B$34*0.85/$J$34,0)*$J$34),"") | E32: 3 - 5 | I32: Equipamento | J32: Polia
